File: analise_tracao/ensiao_tracao_cp_2.csv
Position (mm);Force (N);Strain (%);Time (min)
0,00;1,67;0,000333;0,00363
0,00400;77,9;0,000865;0,00844
0,00900;175;0,00150;0,0132
0,0140;247;0,00200;0,0181
0,0190;170;-0,000558;0,0229
0,0236;190;-0,00133;0,0277
0,0288;203;-0,00213;0,0325
0,0330;222;-0,00301;0,0373
0,0380;258;-0,00350;0,0421
0,0430;303;-0,00333;0,0469
0,0478;346;-0,00317;0,0517
0,0520;387;-0,00300;0,0565
0,0572;424;-0,00283;0,0614
0,0620;455;-0,00267;0,0662
0,0670;484;-0,00267;0,0710
0,0719;510;-0,00267;0,0758
0,0770;534;-0,00267;0,0806
0,0814;550;-0,00267;0,0854
0,0860;564;-0,00283;0,0902
0,0910;575;-0,00283;0,0950
0,0960;581;-0,00283;0,0998
0,100;577;-0,00300;0,105
0,106;579;-0,00300;0,109
0,110;603;-0,00300;0,114
0,115;635;-0,00267;0,119
0,120;664;-0,00250;0,124
0,125;689;-0,00233;0,129
0,130;694;-0,00233;0,134
0,134;608;-0,00300;0,138
0,139;600;-0,00317;0,143
0,144;586;-0,00333;0,148
0,149;576;-0,00350;0,153
0,154;572;-0,00367;0,158
0,158;575;-0,00367;0,162
0,163;582;-0,00367;0,167
0,168;588;-0,00383;0,172
0,173;596;-0,00379;0,177
0,178;603;-0,00383;0,182
0,182;611;-0,00383;0,186
0,187;623;-0,00383;0,191
0,192;636;-0,00383;0,196
0,197;650;-0,00383;0,201
0,201;662;-0,00383;0,206
0,207;675;-0,00367;0,210
0,211;690;-0,00367;0,215
0,216;705;-0,00367;0,220
0,221;720;-0,00367;0,225
0,225;732;-0,00360;0,230
0,231;750;-0,00350;0,235
0,235;768;-0,00334;0,239
0,240;784;-0,00333;0,244
0,245;798;-0,00333;0,249
0,250;806;-0,00333;0,254
0,255;822;-0,00317;0,259
0,259;835;-0,00317;0,263
0,264;849;-0,00300;0,268
0,269;863;-0,00300;0,273
0,274;878;-0,00286;0,278
0,279;892;-0,00283;0,283
0,283;907;-0,00283;0,287
0,288;924;-0,00267;0,292
0,293;937;-0,00267;0,297
0,298;950;-0,00250;0,302
0,302;964;-0,00250;0,307
0,307;979;-0,00233;0,311
0,312;993;-0,00233;0,316
0,317;1010;-0,00217;0,321
0,322;1020;-0,00217;0,326
0,326;1030;-0,00210;0,331
0,332;1050;-0,00183;0,336
0,336;1060;-0,00183;0,340
0,341;1070;-0,00167;0,345
0,346;1080;-0,00150;0,350
0,351;1100;-0,00150;0,355
0,356;1100;-0,00133;0,360
0,360;1090;-0,00117;0,364
0,365;1100;-0,00117;0,369
0,370;1120;-0,00100;0,374
0,375;1130;-0,00100;0,379
0,380;1140;-0,00100;0,384
0,384;1150;-0,000833;0,388
0,390;1160;-0,000833;0,393
0,394;1170;-0,000667;0,398
0,399;1180;-0,000500;0,403
0,404;1190;-0,000500;0,408
0,408;1210;-0,000333;0,413
0,414;1220;-0,000167;0,417
0,418;1230;-0,000167;0,422
0,423;1240;0,00;0,427
0,428;1260;0,000167;0,432
0,433;1270;0,000167;0,437
0,437;1280;0,000333;0,441
0,442;1300;0,000500;0,446
0,447;1320;0,000667;0,451
0,452;1330;0,000833;0,456
0,457;1350;0,000833;0,461
0,461;1360;0,00102;0,465
0,466;1380;0,00117;0,470
0,471;1400;0,00133;0,475
0,476;1410;0,00150;0,480
0,481;1430;0,00167;0,485
0,485;1440;0,00183;0,489
0,490;1460;0,00200;0,494
0,495;1480;0,00217;0,499
0,500;1490;0,00233;0,504
0,505;1510;0,00250;0,509
0,509;1520;0,00267;0,514
0,515;1540;0,00283;0,518
0,519;1560;0,00299;0,523
0,524;1570;0,00317;0,528
0,529;1590;0,00333;0,533
0,534;1610;0,00350;0,538
0,538;1630;0,00367;0,542
0,543;1650;0,00383;0,547
0,548;1670;0,00400;0,552
0,553;1690;0,00417;0,557
0,558;1710;0,00433;0,562
0,562;1720;0,00450;0,566
0,567;1740;0,00467;0,571
0,572;1760;0,00483;0,576
0,577;1780;0,00500;0,581
0,582;1800;0,00517;0,586
0,586;1820;0,00533;0,591
0,591;1840;0,00557;0,595
0,596;1860;0,00583;0,600
0,601;1880;0,00600;0,605
0,606;1900;0,00617;0,610
0,610;1920;0,00633;0,615
0,616;1940;0,00650;0,619
0,620;1960;0,00681;0,624
0,625;1980;0,00700;0,629
0,630;2010;0,00717;0,634
0,635;2030;0,00733;0,639
0,639;2050;0,00750;0,643
0,644;2070;0,00783;0,648
0,649;2100;0,00800;0,653
0,654;2120;0,00817;0,658
0,659;2140;0,00833;0,663
0,663;2160;0,00867;0,667
0,668;2180;0,00883;0,672
0,673;2210;0,00908;0,677
0,678;2230;0,00933;0,682
0,683;2260;0,00950;0,687
0,687;2280;0,00983;0,692
0,692;2310;0,0100;0,696
0,697;2330;0,0102;0,701
0,702;2350;0,0105;0,706
0,707;2380;0,0107;0,711
0,711;2400;0,0108;0,716
0,717;2420;0,0112;0,720
0,721;2450;0,0113;0,725
0,726;2470;0,0117;0,730
0,731;2500;0,0118;0,735
0,736;2520;0,0120;0,740
0,740;2550;0,0123;0,744
0,745;2570;0,0125;0,749
0,750;2600;0,0127;0,754
0,755;2620;0,0130;0,759
0,760;2650;0,0132;0,764
0,765;2670;0,0133;0,768
0,769;2700;0,0137;0,773
0,774;2720;0,0138;0,778
0,779;2750;0,0140;0,783
0,784;2650;0,0117;0,788
0,789;2320;0,00200;0,793
0,793;2420;0,00267;0,797
0,798;2510;0,00333;0,802
0,803;2600;0,00397;0,807
0,808;2680;0,00450;0,812
0,812;2750;0,00483;0,817
0,818;2800;0,00517;0,821
0,822;2830;0,00550;0,826
0,827;2860;0,00583;0,831
0,832;2880;0,00600;0,836
0,836;2900;0,00617;0,841
0,842;2920;0,00633;0,845
0,846;2950;0,00666;0,850
0,851;2980;0,00683;0,855
0,856;3000;0,00707;0,860
0,861;3030;0,00733;0,865
0,866;3060;0,00750;0,870
0,870;3090;0,00783;0,874
0,875;3110;0,00800;0,879
0,880;3140;0,00817;0,884
0,885;3170;0,00850;0,889
0,889;3200;0,00867;0,894
0,894;3220;0,00900;0,898
0,899;3250;0,00917;0,903
0,904;3280;0,00950;0,908
0,909;3310;0,00967;0,913
0,913;3330;0,0100;0,918
0,919;3360;0,0102;0,922
0,923;3390;0,0105;0,927
0,928;3420;0,0107;0,932
0,933;3450;0,0109;0,937
0,937;3480;0,0112;0,942
0,943;3510;0,0113;0,946
0,947;3530;0,0117;0,951
0,952;3560;0,0118;0,956
0,957;3590;0,0122;0,961
0,962;3620;0,0123;0,966
0,967;3650;0,0125;0,971
0,971;3680;0,0128;0,975
0,976;3710;0,0131;0,980
0,981;3740;0,0133;0,985
0,986;3770;0,0136;0,990
0,990;3800;0,0138;0,995
0,995;3830;0,0140;0,999
1,00;3860;0,0143;1,00
1,00;3890;0,0145;1,01
1,01;3910;0,0148;1,01
1,01;3940;0,0150;1,02
1,02;3970;0,0153;1,02
1,02;4000;0,0155;1,03
1,03;4030;0,0157;1,03
1,03;4060;0,0160;1,04
1,04;4090;0,0162;1,04
1,04;4120;0,0165;1,05
1,05;4150;0,0168;1,05
1,05;4180;0,0170;1,06
1,06;4210;0,0172;1,06
1,06;4240;0,0175;1,07
1,07;4260;0,0177;1,07
1,07;4290;0,0180;1,08
1,08;4320;0,0182;1,08
1,08;4350;0,0185;1,09
1,09;4380;0,0187;1,09
1,09;4410;0,0190;1,10
1,10;4440;0,0192;1,10
1,10;4470;0,0193;1,11
1,11;4500;0,0197;1,11
1,11;4530;0,0200;1,11
1,12;4560;0,0202;1,12
1,12;4590;0,0205;1,12
1,13;4620;0,0208;1,13
1,13;4640;0,0210;1,13
1,14;4670;0,0212;1,14
1,14;4710;0,0215;1,14
1,14;4740;0,0217;1,15
1,15;4760;0,0220;1,15
1,15;4790;0,0222;1,16
1,16;4830;0,0225;1,16
1,16;4860;0,0227;1,17
1,17;4880;0,0230;1,17
1,17;4910;0,0232;1,18
1,18;4940;0,0235;1,18
1,18;4980;0,0237;1,19
1,19;5000;0,0240;1,19
1,19;5030;0,0242;1,20
1,20;5070;0,0245;1,20
1,20;5100;0,0248;1,21
1,21;5130;0,0250;1,21
1,21;5160;0,0252;1,22
1,22;5190;0,0255;1,22
1,22;5220;0,0258;1,23
1,23;5250;0,0260;1,23
1,23;5280;0,0263;1,24
1,24;5310;0,0265;1,24
1,24;5340;0,0268;1,24
1,25;5380;0,0272;1,25
1,25;5400;0,0273;1,25
1,26;5440;0,0277;1,26
1,26;5470;0,0278;1,26
1,27;5500;0,0282;1,27
1,27;5530;0,0285;1,27
1,27;5560;0,0287;1,28
1,28;5600;0,0290;1,28
1,28;5630;0,0293;1,29
1,29;5660;0,0295;1,29
1,29;5690;0,0298;1,30
1,30;5720;0,0302;1,30
1,30;5760;0,0303;1,31
1,31;5790;0,0307;1,31
1,31;5820;0,0308;1,32
1,32;5850;0,0312;1,32
1,32;5890;0,0315;1,33
1,33;5920;0,0317;1,33
1,33;5950;0,0320;1,34
1,34;5980;0,0323;1,34
1,34;6020;0,0325;1,35
1,35;6050;0,0327;1,35
1,35;6080;0,0330;1,36
1,36;6110;0,0333;1,36
1,36;6150;0,0337;1,36
1,37;6180;0,0339;1,37
1,37;6210;0,0342;1,37
1,38;6250;0,0345;1,38
1,38;6280;0,0347;1,38
1,39;6310;0,0350;1,39
1,39;6350;0,0353;1,39
1,39;6380;0,0355;1,40
1,40;6410;0,0358;1,40
1,40;6450;0,0362;1,41
1,41;6480;0,0363;1,41
1,41;6510;0,0367;1,42
1,42;6550;0,0370;1,42
1,42;6580;0,0373;1,43
1,43;6610;0,0375;1,43
1,43;6650;0,0378;1,44
1,44;6680;0,0381;1,44
1,44;6710;0,0383;1,45
1,45;6750;0,0386;1,45
1,45;6780;0,0390;1,46
1,46;6810;0,0392;1,46
1,46;6850;0,0395;1,47
1,47;6880;0,0398;1,47
1,47;6920;0,0400;1,48
1,48;6950;0,0403;1,48
1,48;6990;0,0407;1,49
1,49;7020;0,0410;1,49
1,49;7050;0,0412;1,49
1,50;7090;0,0415;1,50
1,50;7130;0,0418;1,50
1,51;7160;0,0420;1,51
1,51;7190;0,0423;1,51
1,51;7230;0,0426;1,52
1,52;7260;0,0428;1,52
1,52;7300;0,0432;1,53
1,53;7330;0,0435;1,53
1,53;7360;0,0438;1,54
1,54;7400;0,0442;1,54
1,54;7430;0,0444;1,55
1,55;7470;0,0447;1,55
1,55;7500;0,0448;1,56
1,56;7540;0,0452;1,56
1,56;7570;0,0455;1,57
1,57;7610;0,0457;1,57
1,57;7640;0,0460;1,58
1,58;7670;0,0463;1,58
1,58;7710;0,0467;1,59
1,59;7740;0,0470;1,59
1,59;7780;0,0472;1,60
1,60;7810;0,0475;1,60
1,60;7850;0,0478;1,61
1,61;7880;0,0482;1,61
1,61;7920;0,0483;1,62
1,62;7950;0,0487;1,62
1,62;7990;0,0490;1,62
1,63;8020;0,0493;1,63
1,63;8060;0,0495;1,63
1,64;8090;0,0498;1,64
1,64;8130;0,0502;1,64
1,64;8160;0,0504;1,65
1,65;8200;0,0507;1,65
1,65;8230;0,0510;1,66
1,66;8270;0,0513;1,66
1,66;8310;0,0517;1,67
1,67;8340;0,0519;1,67
1,67;8370;0,0522;1,68
1,68;8410;0,0525;1,68
1,68;8450;0,0528;1,69
1,69;8480;0,0532;1,69
1,69;8520;0,0533;1,70
1,70;8550;0,0537;1,70
1,70;8590;0,0540;1,71
1,71;8620;0,0543;1,71
1,71;8660;0,0547;1,72
1,72;8690;0,0549;1,72
1,72;8730;0,0552;1,73
1,73;8770;0,0555;1,73
1,73;8800;0,0558;1,74
1,74;8840;0,0562;1,74
1,74;8870;0,0565;1,75
1,75;8910;0,0568;1,75
1,75;8940;0,0571;1,75
1,76;8980;0,0573;1,76
1,76;9020;0,0577;1,76
1,77;9050;0,0580;1,77
1,77;9090;0,0583;1,77
1,78;9120;0,0585;1,78
1,78;9160;0,0588;1,78
1,78;9200;0,0592;1,79
1,79;9230;0,0595;1,79
1,79;9270;0,0598;1,80
1,80;9300;0,0602;1,80
1,80;9340;0,0605;1,81
1,81;9380;0,0607;1,81
1,81;9410;0,0610;1,82
1,82;9440;0,0613;1,82
1,82;9480;0,0617;1,83
1,83;9520;0,0620;1,83
1,83;9550;0,0623;1,84
1,84;9590;0,0625;1,84
1,84;9620;0,0628;1,85
1,85;9660;0,0632;1,85
1,85;9700;0,0635;1,86
1,86;9730;0,0638;1,86
1,86;9770;0,0640;1,87
1,87;9810;0,0645;1,87
1,87;9840;0,0648;1,87
1,88;9880;0,0650;1,88
1,88;9910;0,0653;1,88
1,89;9950;0,0657;1,89
1,89;9990;0,0660;1,89
1,89;10000;0,0663;1,90
1,90;10100;0,0667;1,90
1,90;10100;0,0670;1,91
1,91;10100;0,0673;1,91
1,91;10200;0,0675;1,92
1,92;10200;0,0679;1,92
1,92;10200;0,0682;1,93
1,93;10300;0,0685;1,93
1,93;10300;0,0688;1,94
1,94;10400;0,0692;1,94
1,94;10400;0,0695;1,95
1,95;10400;0,0698;1,95
1,95;10500;0,0701;1,96
1,96;10500;0,0703;1,96
1,96;10500;0,0707;1,97
1,97;10600;0,0711;1,97
1,97;10600;0,0713;1,98
1,98;10700;0,0717;1,98
1,98;10700;0,0720;1,99
1,99;10700;0,0723;1,99
1,99;10800;0,0726;2,00
2,00;10800;0,0730;2,00
2,00;10800;0,0732;2,00
2,01;10900;0,0735;2,01
2,01;10900;0,0739;2,01
2,02;11000;0,0742;2,02
2,02;11000;0,0745;2,02
2,02;11000;0,0748;2,03
2,03;11100;0,0752;2,03
2,03;11100;0,0755;2,04
2,04;11100;0,0758;2,04
2,04;11200;0,0761;2,05
2,05;11200;0,0765;2,05
2,05;11300;0,0767;2,06
2,06;11300;0,0770;2,06
2,06;11300;0,0773;2,07
2,07;11400;0,0777;2,07
2,07;11400;0,0780;2,08
2,08;11400;0,0783;2,08
2,08;11500;0,0787;2,09
2,09;11500;0,0790;2,09
2,09;11600;0,0793;2,10
2,10;11600;0,0796;2,10
2,10;11600;0,0798;2,11
2,11;11700;0,0803;2,11
2,11;11700;0,0805;2,12
2,12;11700;0,0808;2,12
2,12;11800;0,0812;2,13
2,13;11800;0,0815;2,13
2,13;11900;0,0820;2,13
2,14;11900;0,0822;2,14
2,14;11900;0,0825;2,14
2,15;12000;0,0828;2,15
2,15;12000;0,0832;2,15
2,16;12100;0,0835;2,16
2,16;12100;0,0838;2,16
2,16;12100;0,0842;2,17
2,17;12200;0,0845;2,17
2,17;12200;0,0848;2,18
2,18;12200;0,0852;2,18
2,18;12300;0,0855;2,19
2,19;12300;0,0858;2,19
2,19;12400;0,0862;2,20
2,20;12400;0,0865;2,20
2,20;12400;0,0868;2,21
2,21;12500;0,0872;2,21
2,21;12500;0,0875;2,22
2,22;12500;0,0878;2,22
2,22;12600;0,0882;2,23
2,23;12600;0,0885;2,23
2,23;12700;0,0888;2,24
2,24;12700;0,0892;2,24
2,24;12700;0,0895;2,25
2,25;12800;0,0898;2,25
2,25;12800;0,0902;2,25
2,26;12900;0,0905;2,26
2,26;12900;0,0910;2,26
2,27;12900;0,0912;2,27
2,27;13000;0,0916;2,27
2,28;13000;0,0919;2,28
2,28;13000;0,0922;2,28
2,28;13100;0,0925;2,29
2,29;13100;0,0929;2,29
2,29;13200;0,0932;2,30
2,30;13200;0,0935;2,30
2,30;13200;0,0938;2,31
2,31;13300;0,0943;2,31
2,31;13300;0,0946;2,32
2,32;13400;0,0950;2,32
2,32;13400;0,0953;2,33
2,33;13400;0,0957;2,33
2,33;13500;0,0960;2,34
2,34;13500;0,0963;2,34
2,34;13500;0,0967;2,35
2,35;13600;0,0970;2,35
2,35;13600;0,0973;2,36
2,36;13700;0,0977;2,36
2,36;13700;0,0980;2,37
2,37;13700;0,0984;2,37
2,37;13800;0,0988;2,38
2,38;13800;0,0992;2,38
2,38;13900;0,0995;2,38
2,39;13900;0,0998;2,39
2,39;13900;0,100;2,39
2,40;14000;0,101;2,40
2,40;14000;0,101;2,40
2,40;14100;0,101;2,41
2,41;14100;0,102;2,41
2,41;14100;0,102;2,42
2,42;14200;0,102;2,42
2,42;14200;0,103;2,43
2,43;14200;0,103;2,43
2,43;14300;0,104;2,44
2,44;14300;0,104;2,44
2,44;14400;0,104;2,45
2,45;14400;0,105;2,45
2,45;14400;0,105;2,46
2,46;14500;0,105;2,46
2,46;14500;0,106;2,47
2,47;14600;0,106;2,47
2,47;14600;0,106;2,48
2,48;14600;0,107;2,48
2,48;14700;0,107;2,49
2,49;14700;0,108;2,49
2,49;14800;0,108;2,50
2,50;14800;0,108;2,50
2,50;14800;0,109;2,51
2,51;14900;0,109;2,51
2,51;14900;0,109;2,51
2,52;15000;0,110;2,52
2,52;15000;0,110;2,52
2,53;15000;0,111;2,53
2,53;15100;0,111;2,53
2,54;15100;0,112;2,54
2,54;15200;0,112;2,54
2,54;15200;0,112;2,55
2,55;15200;0,113;2,55
2,55;15300;0,113;2,56
2,56;15300;0,113;2,56
2,56;15400;0,114;2,57
2,57;15400;0,114;2,57
2,57;15400;0,114;2,58
2,58;15500;0,113;2,58
2,58;15500;0,113;2,59
2,59;15400;0,111;2,59
2,59;15200;0,110;2,60
2,60;15000;0,108;2,60
2,60;14800;0,107;2,61
2,61;14700;0,106;2,61
2,61;14600;0,105;2,62
2,62;14600;0,105;2,62
2,62;14500;0,105;2,63
2,63;14400;0,105;2,63
2,63;14400;0,105;2,63
2,64;14300;0,105;2,64
2,64;14300;0,105;2,64
2,65;14300;0,105;2,65
2,65;14300;0,106;2,65
2,66;14300;0,107;2,66
2,66;14300;0,108;2,66
2,66;14300;0,109;2,67
2,67;14300;0,111;2,67
2,67;14200;0,113;2,68
2,68;14200;0,115;2,68
2,68;14100;0,118;2,69
2,69;14100;0,122;2,69
2,69;14000;0,126;2,70
2,70;14000;0,131;2,70
2,70;13900;0,137;2,71
2,71;13900;0,143;2,71
2,71;13900;0,149;2,72
2,72;13900;0,156;2,72
2,72;13900;0,164;2,73
2,73;13900;0,173;2,73
2,73;13800;0,184;2,74
2,74;13800;0,194;2,74
2,74;13800;0,205;2,75
2,75;13800;0,216;2,75
2,75;13800;0,225;2,76
2,76;13800;0,234;2,76
2,76;13800;0,243;2,76
2,77;13800;0,252;2,77
2,77;13800;0,261;2,77
2,78;13800;0,271;2,78
2,78;13800;0,280;2,78
2,78;13800;0,289;2,79
2,79;13800;0,298;2,79
2,79;13800;0,307;2,80
2,80;13800;0,317;2,80
2,80;13800;0,327;2,81
2,81;13800;0,338;2,81
2,81;13800;0,350;2,82
2,82;13800;0,362;2,82
2,82;13700;0,374;2,83
2,83;13700;0,386;2,83
2,83;13700;0,398;2,84
2,84;13700;0,409;2,84
2,84;13600;0,420;2,85
2,85;13600;0,431;2,85
2,85;13600;0,441;2,86
2,86;13600;0,450;2,86
2,86;13600;0,459;2,87
2,87;13600;0,468;2,87
2,87;13600;0,477;2,88
2,88;13600;0,486;2,88
2,88;13600;0,497;2,89
2,89;13600;0,506;2,89
2,89;13600;0,515;2,89
2,90;13600;0,524;2,90
2,90;13700;0,532;2,90
2,91;13700;0,541;2,91
2,91;13700;0,550;2,91
2,91;13700;0,558;2,92
2,92;13700;0,566;2,92
2,92;13700;0,574;2,93
2,93;13700;0,582;2,93
2,93;13800;0,591;2,94
2,94;13800;0,601;2,94
2,94;13800;0,610;2,95
2,95;13800;0,620;2,95
2,95;13800;0,630;2,96
2,96;13800;0,640;2,96
2,96;13800;0,649;2,97
2,97;13800;0,659;2,97
2,97;13800;0,669;2,98
2,98;13700;0,679;2,98
2,98;13700;0,690;2,99
2,99;13700;0,700;2,99
2,99;13700;0,711;3,00
3,00;13700;0,720;3,00
3,00;13700;0,730;3,01
3,01;13700;0,740;3,01
3,01;13700;0,752;3,01
3,02;13700;0,764;3,02
3,02;13600;0,776;3,02
3,03;13600;0,788;3,03
3,03;13600;0,800;3,03
3,04;13600;0,812;3,04
3,04;13600;0,822;3,04
3,04;13500;0,833;3,05
3,05;13500;0,842;3,05
3,05;13500;0,851;3,06
3,06;13600;0,861;3,06
3,06;13600;0,870;3,07
3,07;13600;0,879;3,07
3,07;13600;0,888;3,08
3,08;13600;0,897;3,08
3,08;13600;0,905;3,09
3,09;13600;0,913;3,09
3,09;13600;0,920;3,10
3,10;13700;0,927;3,10
3,10;13700;0,935;3,11
3,11;13700;0,942;3,11
3,11;13800;0,948;3,12
3,12;13800;0,955;3,12
3,12;13800;0,962;3,13
3,13;13900;0,969;3,13
3,13;13900;0,975;3,14
3,14;13900;0,982;3,14
3,14;14000;0,989;3,14
3,15;14000;0,997;3,15
3,15;14000;1,00;3,15
3,16;14000;1,01;3,16
3,16;14100;1,02;3,16
3,17;14100;1,03;3,17
3,17;14100;1,04;3,17
3,17;14100;1,05;3,18
3,18;14100;1,06;3,18
3,18;14100;1,06;3,19
3,19;14100;1,08;3,19
3,20;14000;1,10;3,20
3,20;14000;1,10;3,20
3,20;14000;1,10;3,21
3,21;14000;1,10;3,21
3,21;13900;1,10;3,22
3,22;13800;1,10;3,22
3,22;13800;1,10;3,23
3,23;13800;1,10;3,23
3,23;13700;1,10;3,24
3,24;13700;1,10;3,24
3,24;13700;1,10;3,25
3,25;13700;1,10;3,25
3,25;13700;1,10;3,26
3,26;13600;1,10;3,26
3,26;13600;1,10;3,27
3,27;13600;1,10;3,27
3,27;13600;1,10;3,28
3,28;13600;1,10;3,28
3,28;13600;1,10;3,28
3,29;13600;1,10;3,29
3,29;13600;1,10;3,29
3,30;13600;1,10;3,30
3,30;13600;1,10;3,30
3,31;13600;1,10;3,31
3,31;13600;1,10;3,31
3,31;13600;1,10;3,32
3,32;13600;1,10;3,32
3,32;13700;1,10;3,33
3,33;13700;1,10;3,33
3,33;13700;1,10;3,34
3,34;13700;1,10;3,34
3,34;13700;1,10;3,35
3,35;13700;1,10;3,35
3,35;13700;1,10;3,36
3,36;13700;1,10;3,36
3,36;13700;1,10;3,37
3,37;13800;1,10;3,37
3,37;13800;1,10;3,38
3,38;13800;1,10;3,38
3,38;13700;1,10;3,39
3,39;13700;1,10;3,39
3,39;13700;1,10;3,40
3,40;13700;1,10;3,40
3,40;13600;1,10;3,41
3,41;13600;1,10;3,41
3,41;13600;1,10;3,42
3,42;13600;1,10;3,42
3,42;13500;1,10;3,43
3,43;13500;1,10;3,43
3,43;13500;1,10;3,43
3,44;13500;1,10;3,44
3,44;13500;1,10;3,44
3,45;13500;1,10;3,45
3,45;13500;1,10;3,45
3,46;13500;1,10;3,46
3,46;13500;1,10;3,46
3,46;13500;1,10;3,47
3,47;13500;1,10;3,47
3,47;13500;1,10;3,48
3,48;13400;1,10;3,48
3,48;13400;1,10;3,49
3,49;13500;1,10;3,49
3,49;13500;1,10;3,50
3,50;13500;1,10;3,50
3,50;13500;1,10;3,51
3,51;13500;1,10;3,51
3,51;13600;1,10;3,52
3,52;13600;1,10;3,52
3,52;13600;1,10;3,53
3,53;13600;1,10;3,53
3,53;13600;1,10;3,54
3,54;13600;1,10;3,54
3,54;13600;1,10;3,55
3,55;13600;1,10;3,55
3,55;13600;1,10;3,56
3,56;13600;1,10;3,56
3,56;13600;1,10;3,57
3,57;13500;1,10;3,57
3,57;13500;1,10;3,58
3,58;13500;1,10;3,58
3,58;13500;1,10;3,58
3,59;13500;1,10;3,59
3,59;13500;1,10;3,59
3,60;13500;1,10;3,60
3,60;13500;1,10;3,60
3,61;13500;1,10;3,61
3,61;13500;1,10;3,61
3,61;13400;1,10;3,62
3,62;13400;1,10;3,62
3,62;13400;1,10;3,63
3,63;13400;1,10;3,63
3,63;13400;1,10;3,64
3,64;13400;1,10;3,64
3,64;13400;1,10;3,65
3,65;13400;1,10;3,65
3,65;13400;1,10;3,66
3,66;13400;1,10;3,66
3,66;13400;1,10;3,67
3,67;13400;1,10;3,67
3,67;13500;1,10;3,68
3,68;13500;1,10;3,68
3,68;13500;1,10;3,69
3,69;13500;1,10;3,69
3,69;13500;1,10;3,70
3,70;13500;1,10;3,70
3,70;13500;1,10;3,71
3,71;13500;1,10;3,71
3,71;13500;1,10;3,72
3,72;13500;1,10;3,72
3,72;13500;1,10;3,73
3,73;13500;1,10;3,73
3,73;13500;1,10;3,73
3,74;13500;1,10;3,74
3,74;13500;1,10;3,74
3,75;13500;1,10;3,75
3,75;13500;1,10;3,75
3,76;13500;1,10;3,76
3,76;13500;1,10;3,76
3,76;13400;1,10;3,77
3,77;13400;1,10;3,77
3,77;13400;1,10;3,78
3,78;13400;1,10;3,78
3,78;13400;1,10;3,79
3,79;13400;1,10;3,79
3,79;13400;1,10;3,80
3,80;13400;1,10;3,80
3,80;13400;1,10;3,81
3,81;13400;1,10;3,81
3,81;13400;1,10;3,82
3,82;13400;1,10;3,82
3,82;13400;1,10;3,83
3,83;13500;1,10;3,83
3,83;13500;1,10;3,84
3,84;13500;1,10;3,84
3,84;13600;1,10;3,85
3,85;13600;1,10;3,85
3,85;13600;1,10;3,86
3,86;13700;1,10;3,86
3,87;13800;1,10;3,87
3,87;13800;1,10;3,87
3,94;14800;1,10;3,88
4,04;15200;1,10;3,88
4,14;15500;1,10;3,88
4,23;15700;1,10;3,89
4,33;16000;1,10;3,89
4,42;16200;1,10;3,90
4,52;16400;1,10;3,90
4,62;16600;1,10;3,91
4,71;16700;1,10;3,91
4,81;16900;1,10;3,92
4,90;17100;1,10;3,92
5,00;17200;1,10;3,93
5,10;17400;1,10;3,93
5,19;17600;1,10;3,94
5,29;17700;1,10;3,94
5,38;17900;1,10;3,95
5,48;18000;1,10;3,95
5,58;18100;1,10;3,96
5,67;18300;1,10;3,96
5,77;18400;1,10;3,97
5,87;18500;1,10;3,97
5,96;18700;1,10;3,98
6,06;18800;1,10;3,98
6,15;18900;1,10;3,99
6,25;19000;1,10;3,99
6,35;19100;1,10;4,00
6,44;19200;1,10;4,00
6,54;19300;1,10;4,01
6,63;19400;1,10;4,01
6,73;19500;1,10;4,01
6,83;19600;1,10;4,02
6,92;19700;1,10;4,02
7,02;19800;1,10;4,03
7,12;19900;1,10;4,03
7,21;20000;1,10;4,04
7,31;20000;1,10;4,04
7,40;20100;1,10;4,05
7,50;20200;1,10;4,05
7,60;20300;1,10;4,06
7,69;20300;1,10;4,06
7,79;20400;1,10;4,07
7,88;20500;1,10;4,07
7,98;20600;1,10;4,08
8,08;20600;1,10;4,08
8,17;20700;1,10;4,09
8,27;20700;1,10;4,09
8,37;20800;1,10;4,10
8,46;20900;1,10;4,10
8,56;20900;1,10;4,11
8,65;21000;1,10;4,11
8,75;21000;1,10;4,12
8,85;21100;1,10;4,12
8,94;21100;1,10;4,13
9,04;21100;1,10;4,13
9,14;21200;1,10;4,13
9,23;21200;1,10;4,14
9,33;21300;1,10;4,14
9,42;21300;1,10;4,15
9,52;21400;1,10;4,15
9,62;21400;1,10;4,16
9,71;21500;1,10;4,16
9,81;21500;1,10;4,17
9,90;21500;1,10;4,17
10,0;21600;1,10;4,18
10,1;21600;1,10;4,18
10,2;21700;1,10;4,19
10,3;21700;1,10;4,19
10,4;21700;1,10;4,20
10,5;21800;1,10;4,20
10,6;21800;1,10;4,21
10,7;21800;1,10;4,21
10,8;21900;1,10;4,22
10,9;21900;1,10;4,22
11,0;21900;1,10;4,23
11,1;21900;1,10;4,23
11,2;22000;1,10;4,24
11,2;22000;1,10;4,24
11,3;22000;1,10;4,25
11,4;22100;1,10;4,25
11,5;22100;1,10;4,26
11,6;22100;1,10;4,26
11,7;22100;1,10;4,26
11,8;22200;1,10;4,27
11,9;22200;1,10;4,27
12,0;22200;1,10;4,28
12,1;22200;1,10;4,28
12,2;22200;1,10;4,29
12,3;22300;1,10;4,29
12,4;22300;1,10;4,30
12,5;22300;1,10;4,30
12,6;22300;1,10;4,31
12,7;22300;1,10;4,31
12,8;22300;1,10;4,32
12,9;22400;1,10;4,32
13,0;22400;1,10;4,33
13,1;22400;1,10;4,33
13,2;22400;1,10;4,34
13,3;22400;1,10;4,34
13,4;22400;1,10;4,35
13,5;22400;1,10;4,35
13,6;22500;1,10;4,36
13,7;22500;1,10;4,36
13,7;22500;1,10;4,37
13,8;22500;1,10;4,37
13,9;22500;1,10;4,38
14,0;22500;1,10;4,38
14,1;22500;1,10;4,38
14,2;22500;1,10;4,39
14,3;22500;1,10;4,39
14,4;22500;1,10;4,40
14,5;22500;1,10;4,40
14,6;22500;1,10;4,41
14,7;22500;1,10;4,41
14,8;22600;1,10;4,42
14,9;22600;1,10;4,42
15,0;22600;1,10;4,43
15,1;22600;1,10;4,43
15,2;22600;1,10;4,44
15,3;22600;1,10;4,44
15,4;22600;1,10;4,45
15,5;22600;1,10;4,45
15,6;22600;1,10;4,46
15,7;22600;1,10;4,46
15,8;22600;1,10;4,47
15,9;22600;1,10;4,47
16,0;22600;1,10;4,48
16,1;22600;1,10;4,48
16,2;22600;1,10;4,49
16,2;22600;1,10;4,49
16,3;22600;1,10;4,50
16,4;22600;1,10;4,50
16,5;22600;1,10;4,51
16,6;22600;1,10;4,51
16,7;22600;1,10;4,51
16,8;22600;1,10;4,52
16,9;22600;1,10;4,52
17,0;22500;1,10;4,53
17,1;22500;1,10;4,53
17,2;22500;1,10;4,54
17,3;22500;1,10;4,54
17,4;22500;1,10;4,55
17,5;22500;1,10;4,55
17,6;22500;1,10;4,56
17,7;22500;1,10;4,56
17,8;22500;1,10;4,57
17,9;22500;1,10;4,57
18,0;22500;1,10;4,58
18,1;22400;1,10;4,58
18,2;22400;1,10;4,59
18,3;22400;1,10;4,59
18,4;22400;1,10;4,60
18,5;22400;1,10;4,60
18,6;22400;1,10;4,61
18,7;22300;1,10;4,61
18,7;22300;1,10;4,62
18,8;22300;1,10;4,62
18,9;22300;1,10;4,63
19,0;22200;1,10;4,63
19,1;22200;1,10;4,63
19,2;22200;1,10;4,64
19,3;22100;1,10;4,64
19,4;22100;1,10;4,65
19,5;22100;1,10;4,65
19,6;22000;1,10;4,66
19,7;21900;1,10;4,66
19,8;21900;1,10;4,67
19,9;21800;1,10;4,67
20,0;21700;1,10;4,68
20,1;21700;1,10;4,68
20,2;21600;1,10;4,69
20,3;21500;1,10;4,69
20,4;21400;1,10;4,70
20,5;21300;1,10;4,70
20,6;21100;1,10;4,71
20,7;21000;1,10;4,71
20,8;20900;1,10;4,72
20,9;20800;1,10;4,72
21,0;20600;1,10;4,73
21,1;20500;1,10;4,73
21,2;20300;1,10;4,74
21,2;20100;1,10;4,74
21,3;19900;1,10;4,75
21,4;19700;1,10;4,75
21,5;19500;1,10;4,76
21,6;19300;1,10;4,76
21,7;19100;1,10;4,76
21,8;18900;1,10;4,77
21,9;18600;1,10;4,77
22,0;18400;1,10;4,78
22,1;18100;1,10;4,78
22,2;17800;1,10;4,79
22,3;17500;1,10;4,79
22,4;17100;1,10;4,80
22,5;16800;1,10;4,80
22,6;16400;1,10;4,81
22,8;4290;1,10;4,82