File: analise_tracao/enT1_copia.csv
Position (mm),Force (N),Strain (%),Time (min)
"0,00","0,00","0,00","0,00273"
"0,00335","49,6","0,00123","0,00709"
"0,00800",118,"0,00282","0,0115"
"0,0124",178,"0,00424","0,0158"
"0,0170",229,"0,00562","0,0202"
"0,0211",270,"0,00668","0,0245"
"0,0260",308,"0,00775","0,0289"
"0,0300",346,"0,00881","0,0333"
"0,0342",381,"0,00970","0,0376"
"0,0390",365,"0,00933","0,0420"
"0,0430",400,"0,0102","0,0463"
"0,0473",424,"0,0108","0,0507"
"0,0520",444,"0,0113","0,0551"
"0,0561",462,"0,0118","0,0594"
"0,0605",477,"0,0122","0,0638"
"0,0650",485,"0,0123","0,0681"
"0,0692",482,"0,0122","0,0725"
"0,0736",471,"0,0117","0,0769"
"0,0780",453,"0,0110","0,0812"
"0,0823",435,"0,0103","0,0856"
"0,0870",433,"0,0103","0,0899"
"0,0911",435,"0,0102","0,0943"
"0,0954",439,"0,0102","0,0987"
"0,100",450,"0,0103","0,103"
"0,104",472,"0,0109","0,107"
"0,109",499,"0,0115","0,112"
"0,113",528,"0,0123","0,116"
"0,117",556,"0,0130","0,120"
"0,122",586,"0,0137","0,125"
"0,126",615,"0,0143","0,129"
"0,130",641,"0,0151","0,134"
"0,135",669,"0,0158","0,138"
"0,139",697,"0,0164","0,142"
"0,144",725,"0,0171","0,147"
"0,148",751,"0,0177","0,151"
"0,152",776,"0,0183","0,155"
"0,157",804,"0,0190","0,160"
"0,161",828,"0,0196","0,164"
"0,165",853,"0,0202","0,168"
"0,170",879,"0,0208","0,173"
"0,174",904,"0,0214","0,177"
"0,178",928,"0,0220","0,182"
"0,183",954,"0,0226","0,186"
"0,187",978,"0,0231","0,190"
"0,191",1000,"0,0237","0,195"
"0,196",1030,"0,0241","0,199"
"0,200",1050,"0,0246","0,203"
"0,204",852,"0,0172","0,208"
"0,209",888,"0,0178","0,212"
"0,213",937,"0,0188","0,216"
"0,218",980,"0,0197","0,221"
"0,222",1020,"0,0206","0,225"
"0,226",1060,"0,0213","0,229"
"0,231",1080,"0,0218","0,234"
"0,235",1100,"0,0222","0,238"
"0,239",1120,"0,0227","0,243"
"0,244",1150,"0,0232","0,247"
"0,248",1170,"0,0235","0,251"
"0,252",1190,"0,0240","0,256"
"0,257",1210,"0,0245","0,260"
"0,261",1230,"0,0248","0,264"
"0,265",1250,"0,0253","0,269"
"0,270",1270,"0,0258","0,273"
"0,274",1290,"0,0262","0,277"
"0,279",1310,"0,0267","0,282"
"0,283",1330,"0,0272","0,286"
"0,287",1360,"0,0275","0,291"
"0,292",1370,"0,0280","0,295"
"0,296",1400,"0,0283","0,299"
"0,300",1410,"0,0288","0,304"
"0,305",1430,"0,0292","0,308"
"0,309",1450,"0,0295","0,312"
"0,314",1470,"0,0300","0,317"
"0,318",1490,"0,0303","0,321"
"0,322",1500,"0,0307","0,325"
"0,327",1520,"0,0310","0,330"
"0,331",1540,"0,0315","0,334"
"0,335",1560,"0,0318","0,339"
"0,340",1570,"0,0322","0,343"
"0,344",1590,"0,0325","0,347"
"0,349",1610,"0,0329","0,352"
"0,353",1620,"0,0333","0,356"
"0,357",1640,"0,0337","0,360"
"0,362",1650,"0,0339","0,365"
"0,366",1670,"0,0343","0,369"
"0,370",1690,"0,0346","0,373"
"0,375",1700,"0,0350","0,378"
"0,379",1720,"0,0352","0,382"
"0,384",1740,"0,0356","0,386"
"0,388",1750,"0,0358","0,391"
"0,392",1770,"0,0362","0,395"
"0,397",1780,"0,0366","0,400"
"0,401",1800,"0,0368","0,404"
"0,405",1810,"0,0372","0,408"
"0,410",1830,"0,0375","0,413"
"0,414",1850,"0,0380","0,417"
"0,418",1860,"0,0382","0,421"
"0,423",1870,"0,0387","0,426"
"0,427",1890,"0,0389","0,430"
"0,432",1910,"0,0391","0,434"
"0,436",1920,"0,0395","0,439"
"0,440",1940,"0,0398","0,443"
"0,445",1950,"0,0402","0,448"
"0,449",1970,"0,0405","0,452"
"0,453",1980,"0,0408","0,456"
"0,458",2000,"0,0412","0,461"
"0,462",2010,"0,0415","0,465"
"0,466",2030,"0,0418","0,469"
"0,471",2050,"0,0422","0,474"
"0,475",2060,"0,0425","0,478"
"0,479",2080,"0,0428","0,482"
"0,484",2090,"0,0432","0,487"
"0,488",2110,"0,0435","0,491"
"0,492",2120,"0,0438","0,496"
"0,497",2140,"0,0442","0,500"
"0,501",2150,"0,0445","0,504"
"0,505",2170,"0,0448","0,509"
"0,510",2190,"0,0452","0,513"
"0,514",2200,"0,0455","0,517"
"0,519",2220,"0,0458","0,522"
"0,523",2240,"0,0462","0,526"
"0,527",2250,"0,0465","0,530"
"0,531",2270,"0,0469","0,535"
"0,536",2280,"0,0473","0,539"
"0,540",2300,"0,0477","0,543"
"0,544",2320,"0,0479","0,548"
"0,549",2330,"0,0483","0,552"
"0,553",2350,"0,0487","0,557"
"0,557",2360,"0,0489","0,561"
"0,562",2380,"0,0493","0,565"
"0,566",2400,"0,0497","0,570"
"0,571",2410,"0,0500","0,574"
"0,575",2430,"0,0503","0,578"
"0,579",2450,"0,0507","0,583"
"0,584",2460,"0,0510","0,587"
"0,588",2480,"0,0513","0,591"
"0,592",2500,"0,0517","0,596"
"0,597",2510,"0,0520","0,600"
"0,601",2530,"0,0523","0,605"
"0,606",2550,"0,0527","0,609"
"0,610",2560,"0,0530","0,613"
"0,614",2580,"0,0533","0,618"
"0,619",2600,"0,0537","0,622"
"0,623",2610,"0,0540","0,626"
"0,627",2630,"0,0543","0,631"
"0,632",2650,"0,0547","0,635"
"0,636",2660,"0,0550","0,639"
"0,641",2680,"0,0554","0,644"
"0,645",2700,"0,0557","0,648"
"0,649",2710,"0,0561","0,653"
"0,654",2730,"0,0564","0,657"
"0,658",2750,"0,0568","0,661"
"0,662",2770,"0,0572","0,666"
"0,667",2780,"0,0575","0,670"
"0,671",2800,"0,0577","0,674"
"0,676",2820,"0,0582","0,679"
"0,680",2830,"0,0585","0,683"
"0,684",2850,"0,0588","0,687"
"0,689",2870,"0,0592","0,692"
"0,693",2880,"0,0595","0,696"
"0,697",2900,"0,0598","0,700"
"0,702",2920,"0,0602","0,705"
"0,706",2940,"0,0607","0,709"
"0,711",2960,"0,0611","0,714"
"0,715",2570,"0,0343","0,718"
"0,719",2530,"0,0255","0,722"
"0,724",2600,"0,0271","0,727"
"0,728",2660,"0,0287","0,731"
"0,732",2730,"0,0301","0,735"
"0,737",2790,"0,0313","0,740"
"0,741",2850,"0,0327","0,744"
"0,746",2910,"0,0339","0,748"
"0,750",2950,"0,0350","0,753"
"0,754",2990,"0,0357","0,757"
"0,759",3010,"0,0362","0,762"
"0,763",3030,"0,0365","0,766"
"0,767",3050,"0,0368","0,770"
"0,772",3060,"0,0373","0,775"
"0,776",3080,"0,0377","0,779"
"0,780",3100,"0,0381","0,783"
"0,785",3120,"0,0385","0,788"
"0,789",3140,"0,0389","0,792"
"0,793",3160,"0,0393","0,796"
"0,798",3180,"0,0398","0,801"
"0,802",3200,"0,0402","0,805"
"0,806",3220,"0,0406","0,810"
"0,811",3240,"0,0410","0,814"
"0,815",3260,"0,0415","0,818"
"0,820",3280,"0,0418","0,823"
"0,824",3300,"0,0423","0,827"
"0,828",3320,"0,0428","0,831"
"0,833",3340,"0,0433","0,836"
"0,837",3360,"0,0437","0,840"
"0,841",3380,"0,0441","0,844"
"0,846",3400,"0,0445","0,849"
"0,850",3420,"0,0449","0,853"
"0,854",3440,"0,0453","0,857"
"0,859",3460,"0,0458","0,862"
"0,863",3480,"0,0463","0,866"
"0,867",3500,"0,0467","0,871"
"0,872",3520,"0,0472","0,875"
"0,876",3540,"0,0477","0,879"
"0,880",3560,"0,0480","0,884"
"0,885",3580,"0,0486","0,888"
"0,889",3600,"0,0491","0,892"
"0,893",3620,"0,0494","0,897"
"0,898",3640,"0,0499","0,901"
"0,902",3660,"0,0505","0,905"
"0,906",3680,"0,0508","0,910"
"0,911",3700,"0,0513","0,914"
"0,915",3730,"0,0518","0,919"
"0,919",3750,"0,0522","0,923"
"0,924",3770,"0,0527","0,927"
"0,929",3790,"0,0532","0,932"
"0,933",3810,"0,0537","0,936"
"0,937",3830,"0,0542","0,940"
"0,941",3850,"0,0546","0,945"
"0,946",3870,"0,0550","0,949"
"0,950",3890,"0,0555","0,953"
"0,954",3910,"0,0560","0,958"
"0,959",3930,"0,0565","0,962"
"0,963",3950,"0,0570","0,967"
"0,968",3980,"0,0575","0,971"
"0,972",4000,"0,0580","0,975"
"0,976",4020,"0,0584","0,980"
"0,981",4040,"0,0588","0,984"
"0,985",4060,"0,0593","0,988"
"0,989",4080,"0,0599","0,993"
"0,994",4100,"0,0603","0,997"
"0,998",4130,"0,0608","1,00"
"1,00",4150,"0,0613","1,01"
"1,01",4170,"0,0618","1,01"
"1,01",4190,"0,0622","1,01"
"1,02",4210,"0,0627","1,02"
"1,02",4230,"0,0632","1,02"
"1,02",4250,"0,0637","1,03"
"1,03",4270,"0,0643","1,03"
"1,03",4300,"0,0647","1,04"
"1,04",4320,"0,0652","1,04"
"1,04",4340,"0,0657","1,05"
"1,05",4360,"0,0662","1,05"
"1,05",4380,"0,0667","1,05"
"1,06",4400,"0,0672","1,06"
"1,06",4420,"0,0677","1,06"
"1,06",4440,"0,0682","1,07"
"1,07",4470,"0,0687","1,07"
"1,07",4490,"0,0692","1,08"
"1,08",4510,"0,0697","1,08"
"1,08",4530,"0,0702","1,08"
"1,09",4550,"0,0707","1,09"
"1,09",4580,"0,0712","1,09"
"1,09",4600,"0,0717","1,10"
"1,10",4620,"0,0722","1,10"
"1,10",4640,"0,0727","1,11"
"1,11",4660,"0,0732","1,11"
"1,11",4680,"0,0737","1,11"
"1,12",4700,"0,0742","1,12"
"1,12",4730,"0,0746","1,12"
"1,13",4750,"0,0752","1,13"
"1,13",4770,"0,0757","1,13"
"1,13",4790,"0,0762","1,14"
"1,14",4820,"0,0767","1,14"
"1,14",4840,"0,0772","1,15"
"1,15",4860,"0,0776","1,15"
"1,15",4880,"0,0782","1,15"
"1,16",4900,"0,0787","1,16"
"1,16",4920,"0,0792","1,16"
"1,16",4950,"0,0797","1,17"
"1,17",4970,"0,0802","1,17"
"1,17",4990,"0,0807","1,18"
"1,18",5010,"0,0812","1,18"
"1,18",5030,"0,0817","1,18"
"1,19",5050,"0,0822","1,19"
"1,19",5080,"0,0828","1,19"
"1,19",5100,"0,0833","1,20"
"1,20",5120,"0,0838","1,20"
"1,20",5140,"0,0843","1,21"
"1,21",5170,"0,0848","1,21"
"1,21",5190,"0,0853","1,22"
"1,22",5210,"0,0858","1,22"
"1,22",5230,"0,0864","1,22"
"1,23",5250,"0,0869","1,23"
"1,23",5280,"0,0875","1,23"
"1,23",5300,"0,0880","1,24"
"1,24",5320,"0,0886","1,24"
"1,24",5340,"0,0892","1,25"
"1,25",5370,"0,0896","1,25"
"1,25",5390,"0,0902","1,25"
"1,26",5410,"0,0907","1,26"
"1,26",5430,"0,0912","1,26"
"1,26",5460,"0,0917","1,27"
"1,27",5480,"0,0922","1,27"
"1,27",5500,"0,0928","1,28"
"1,28",5530,"0,0935","1,28"
"1,28",5550,"0,0939","1,28"
"1,29",5570,"0,0945","1,29"
"1,29",5600,"0,0950","1,29"
"1,30",5620,"0,0955","1,30"
"1,30",5640,"0,0960","1,30"
"1,30",5660,"0,0967","1,31"
"1,31",5690,"0,0972","1,31"
"1,31",5710,"0,0977","1,32"
"1,32",5730,"0,0982","1,32"
"1,32",5760,"0,0988","1,32"
"1,33",5780,"0,0993","1,33"
"1,33",5800,"0,0998","1,33"
"1,33",5830,"0,100","1,34"
"1,34",5850,"0,101","1,34"
"1,34",5870,"0,101","1,35"
"1,35",5900,"0,102","1,35"
"1,35",5920,"0,103","1,35"
"1,36",5940,"0,103","1,36"
"1,36",5970,"0,104","1,36"
"1,36",5990,"0,104","1,37"
"1,37",6010,"0,105","1,37"
"1,37",6040,"0,105","1,38"
"1,38",6060,"0,106","1,38"
"1,38",6090,"0,107","1,39"
"1,39",6110,"0,107","1,39"
"1,39",6130,"0,108","1,39"
"1,40",6160,"0,108","1,40"
"1,40",6180,"0,109","1,40"
"1,40",6200,"0,109","1,41"
"1,41",6230,"0,110","1,41"
"1,41",6250,"0,111","1,42"
"1,42",6280,"0,111","1,42"
"1,42",6300,"0,112","1,42"
"1,43",6320,"0,112","1,43"
"1,43",6350,"0,113","1,43"
"1,43",6370,"0,113","1,44"
"1,44",6400,"0,114","1,44"
"1,44",6420,"0,115","1,45"
"1,45",6450,"0,115","1,45"
"1,45",6470,"0,116","1,45"
"1,46",6490,"0,116","1,46"
"1,46",6520,"0,117","1,46"
"1,47",6540,"0,117","1,47"
"1,47",6570,"0,118","1,47"
"1,47",6590,"0,119","1,48"
"1,48",6620,"0,119","1,48"
"1,48",6640,"0,120","1,49"
"1,49",6660,"0,120","1,49"
"1,49",6690,"0,121","1,49"
"1,50",6710,"0,122","1,50"
"1,50",6740,"0,122","1,50"
"1,50",6760,"0,123","1,51"
"1,51",6790,"0,123","1,51"
"1,51",6810,"0,124","1,52"
"1,52",6830,"0,124","1,52"
"1,52",6860,"0,125","1,52"
"1,53",6880,"0,126","1,53"
"1,53",6910,"0,126","1,53"
"1,54",6940,"0,127","1,54"
"1,54",6960,"0,127","1,54"
"1,54",6980,"0,128","1,55"
"1,55",7010,"0,129","1,55"
"1,55",7040,"0,129","1,56"
"1,56",7060,"0,130","1,56"
"1,56",7080,"0,131","1,56"
"1,57",7110,"0,131","1,57"
"1,57",7130,"0,132","1,57"
"1,57",7160,"0,132","1,58"
"1,58",7190,"0,133","1,58"
"1,58",7210,"0,133","1,59"
"1,59",7230,"0,134","1,59"
"1,59",7260,"0,135","1,59"
"1,60",7280,"0,135","1,60"
"1,60",7310,"0,136","1,60"
"1,60",7340,"0,137","1,61"
"1,61",7360,"0,137","1,61"
"1,61",7380,"0,138","1,62"
"1,62",7410,"0,138","1,62"
"1,62",7440,"0,139","1,63"
"1,63",7460,"0,140","1,63"
"1,63",7490,"0,140","1,63"
"1,64",7510,"0,141","1,64"
"1,64",7540,"0,141","1,64"
"1,64",7560,"0,142","1,65"
"1,65",7590,"0,143","1,65"
"1,65",7610,"0,143","1,66"
"1,66",7640,"0,144","1,66"
"1,66",7670,"0,145","1,66"
"1,67",7690,"0,145","1,67"
"1,67",7710,"0,146","1,67"
"1,67",7740,"0,146","1,68"
"1,68",7770,"0,147","1,68"
"1,68",7790,"0,148","1,69"
"1,69",7820,"0,148","1,69"
"1,69",7850,"0,149","1,69"
"1,70",7870,"0,149","1,70"
"1,70",7900,"0,150","1,70"
"1,71",7920,"0,151","1,71"
"1,71",7950,"0,151","1,71"
"1,71",7970,"0,152","1,72"
"1,72",8000,"0,153","1,72"
"1,72",8020,"0,153","1,73"
"1,73",8050,"0,154","1,73"
"1,73",8080,"0,154","1,73"
"1,74",8100,"0,155","1,74"
"1,74",8130,"0,156","1,74"
"1,74",8150,"0,156","1,75"
"1,75",8180,"0,157","1,75"
"1,75",8200,"0,158","1,76"
"1,76",8230,"0,158","1,76"
"1,76",8260,"0,159","1,76"
"1,77",8280,"0,160","1,77"
"1,77",8310,"0,160","1,77"
"1,77",8330,"0,161","1,78"
"1,78",8360,"0,162","1,78"
"1,78",8380,"0,162","1,79"
"1,79",8410,"0,163","1,79"
"1,79",8440,"0,163","1,80"
"1,80",8460,"0,164","1,80"
"1,80",8490,"0,165","1,80"
"1,81",8510,"0,165","1,81"
"1,81",8540,"0,166","1,81"
"1,81",8570,"0,167","1,82"
"1,82",8590,"0,167","1,82"
"1,82",8620,"0,168","1,83"
"1,83",8650,"0,169","1,83"
"1,83",8670,"0,169","1,83"
"1,84",8700,"0,170","1,84"
"1,84",8720,"0,170","1,84"
"1,84",8750,"0,171","1,85"
"1,85",8770,"0,171","1,85"
"1,85",8800,"0,172","1,86"
"1,86",8830,"0,173","1,86"
"1,86",8860,"0,174","1,86"
"1,87",8880,"0,174","1,87"
"1,87",8910,"0,175","1,87"
"1,87",8930,"0,175","1,88"
"1,88",8960,"0,176","1,88"
"1,88",8990,"0,177","1,89"
"1,89",9010,"0,177","1,89"
"1,89",9040,"0,178","1,90"
"1,90",9070,"0,179","1,90"
"1,90",9090,"0,179","1,90"
"1,91",9120,"0,180","1,91"
"1,91",9140,"0,181","1,91"
"1,91",9170,"0,181","1,92"
"1,92",9200,"0,182","1,92"
"1,92",9220,"0,183","1,93"
"1,93",9250,"0,183","1,93"
"1,93",9280,"0,184","1,93"
"1,94",9300,"0,185","1,94"
"1,94",9330,"0,185","1,94"
"1,94",9360,"0,186","1,95"
"1,95",9390,"0,187","1,95"
"1,95",9410,"0,187","1,96"
"1,96",9440,"0,188","1,96"
"1,96",9460,"0,189","1,97"
"1,97",9490,"0,189","1,97"
"1,97",9520,"0,190","1,97"
"1,98",9540,"0,190","1,98"
"1,98",9570,"0,191","1,98"
"1,98",9600,"0,192","1,99"
"1,99",9620,"0,192","1,99"
"1,99",9650,"0,193","2,00"
"2,00",9680,"0,194","2,00"
"2,00",9700,"0,194","2,00"
"2,01",9730,"0,195","2,01"
"2,01",9760,"0,196","2,01"
"2,01",9780,"0,197","2,02"
"2,02",9810,"0,197","2,02"
"2,02",9840,"0,198","2,03"
"2,03",9870,"0,198","2,03"
"2,03",9890,"0,199","2,03"
"2,04",9920,"0,200","2,04"
"2,04",9950,"0,200","2,04"
"2,04",9970,"0,201","2,05"
"2,05",10000,"0,202","2,05"
"2,05",10000,"0,202","2,06"
"2,06",10100,"0,203","2,06"
"2,06",10100,"0,204","2,07"
"2,07",10100,"0,204","2,07"
"2,07",10100,"0,205","2,07"
"2,08",10200,"0,206","2,08"
"2,08",10200,"0,206","2,08"
"2,08",10200,"0,207","2,09"
"2,09",10200,"0,208","2,09"
"2,09",10300,"0,208","2,10"
"2,10",10300,"0,209","2,10"
"2,10",10300,"0,210","2,10"
"2,11",10300,"0,210","2,11"
"2,11",10400,"0,211","2,11"
"2,12",10400,"0,212","2,12"
"2,12",10400,"0,213","2,12"
"2,12",10500,"0,213","2,13"
"2,13",10500,"0,214","2,13"
"2,13",10500,"0,214","2,14"
"2,14",10500,"0,215","2,14"
"2,14",10600,"0,216","2,14"
"2,15",10600,"0,216","2,15"
"2,15",10600,"0,217","2,15"
"2,15",10600,"0,218","2,16"
"2,16",10700,"0,219","2,16"
"2,16",10700,"0,219","2,17"
"2,17",10700,"0,220","2,17"
"2,17",10800,"0,221","2,17"
"2,18",10800,"0,221","2,18"
"2,18",10800,"0,222","2,18"
"2,18",10800,"0,223","2,19"
"2,19",10900,"0,223","2,19"
"2,19",10900,"0,224","2,20"
"2,20",10900,"0,225","2,20"
"2,20",10900,"0,226","2,21"
"2,21",11000,"0,226","2,21"
"2,21",11000,"0,227","2,21"
"2,22",11000,"0,228","2,22"
"2,22",11100,"0,228","2,22"
"2,22",11100,"0,229","2,23"
"2,23",11100,"0,230","2,23"
"2,23",11100,"0,230","2,24"
"2,24",11200,"0,231","2,24"
"2,24",11200,"0,232","2,24"
"2,25",11200,"0,232","2,25"
"2,25",11200,"0,233","2,25"
"2,25",11300,"0,234","2,26"
"2,26",11300,"0,234","2,26"
"2,26",11300,"0,235","2,27"
"2,27",11400,"0,236","2,27"
"2,27",11400,"0,236","2,27"
"2,28",11400,"0,237","2,28"
"2,28",11400,"0,238","2,28"
"2,28",11500,"0,238","2,29"
"2,29",11500,"0,239","2,29"
"2,29",11500,"0,240","2,30"
"2,30",11600,"0,241","2,30"
"2,30",11600,"0,241","2,31"
"2,31",11600,"0,242","2,31"
"2,31",11600,"0,243","2,31"
"2,32",11700,"0,243","2,32"
"2,32",11700,"0,244","2,32"
"2,32",11700,"0,245","2,33"
"2,33",11700,"0,246","2,33"
"2,33",11800,"0,246","2,34"
"2,34",11800,"0,247","2,34"
"2,34",11800,"0,248","2,34"
"2,35",11900,"0,248","2,35"
"2,35",11900,"0,249","2,35"
"2,35",11900,"0,250","2,36"
"2,36",11900,"0,250","2,36"
"2,36",12000,"0,251","2,37"
"2,37",12000,"0,252","2,37"
"2,37",12000,"0,253","2,38"
"2,38",12100,"0,253","2,38"
"2,38",12100,"0,254","2,38"
"2,39",12100,"0,255","2,39"
"2,39",12100,"0,255","2,39"
"2,39",12200,"0,256","2,40"
"2,40",12200,"0,257","2,40"
"2,40",12200,"0,257","2,41"
"2,41",12200,"0,258","2,41"
"2,41",12300,"0,259","2,41"
"2,42",12300,"0,260","2,42"
"2,42",12300,"0,260","2,42"
"2,42",12400,"0,261","2,43"
"2,43",12400,"0,262","2,43"
"2,43",12400,"0,262","2,44"
"2,44",12400,"0,263","2,44"
"2,44",12500,"0,264","2,44"
"2,45",12500,"0,265","2,45"
"2,45",12500,"0,265","2,45"
"2,46",12600,"0,266","2,46"
"2,46",12600,"0,267","2,46"
"2,46",12600,"0,268","2,47"
"2,47",12600,"0,268","2,47"
"2,47",12700,"0,269","2,48"
"2,48",12700,"0,270","2,48"
"2,48",12700,"0,270","2,48"
"2,49",12800,"0,271","2,49"
"2,49",12800,"0,272","2,49"
"2,49",12800,"0,273","2,50"
"2,50",12800,"0,273","2,50"
"2,50",12900,"0,274","2,51"
"2,51",12900,"0,275","2,51"
"2,51",12900,"0,275","2,51"
"2,52",13000,"0,276","2,52"
"2,52",13000,"0,277","2,52"
"2,52",13000,"0,278","2,53"
"2,53",13000,"0,278","2,53"
"2,53",13100,"0,279","2,54"
"2,54",13100,"0,280","2,54"
"2,54",13100,"0,281","2,55"
"2,55",13100,"0,281","2,55"
"2,55",13200,"0,282","2,55"
"2,56",13200,"0,283","2,56"
"2,56",13200,"0,283","2,56"
"2,56",13300,"0,284","2,57"
"2,57",13300,"0,285","2,57"
"2,57",13300,"0,286","2,58"
"2,58",13300,"0,286","2,58"
"2,58",13400,"0,287","2,58"
"2,59",13400,"0,288","2,59"
"2,59",13400,"0,289","2,59"
"2,59",13500,"0,289","2,60"
"2,60",13500,"0,290","2,60"
"2,60",13500,"0,291","2,61"
"2,61",13500,"0,292","2,61"
"2,61",13600,"0,292","2,61"
"2,62",13600,"0,293","2,62"
"2,62",13600,"0,294","2,62"
"2,63",13700,"0,295","2,63"
"2,63",13700,"0,295","2,63"
"2,63",13700,"0,296","2,64"
"2,64",13700,"0,297","2,64"
"2,64",13800,"0,298","2,65"
"2,65",13800,"0,298","2,65"
"2,65",13800,"0,299","2,65"
"2,66",13900,"0,300","2,66"
"2,66",13900,"0,301","2,66"
"2,66",13900,"0,301","2,67"
"2,67",13900,"0,302","2,67"
"2,67",14000,"0,303","2,68"
"2,68",14000,"0,304","2,68"
"2,68",14000,"0,305","2,68"
"2,69",14100,"0,305","2,69"
"2,69",14100,"0,306","2,69"
"2,70",14100,"0,307","2,70"
"2,70",14100,"0,308","2,70"
"2,70",14200,"0,308","2,71"
"2,71",14200,"0,309","2,71"
"2,71",14200,"0,310","2,72"
"2,72",14300,"0,311","2,72"
"2,72",14300,"0,312","2,72"
"2,73",14300,"0,312","2,73"
"2,73",14300,"0,313","2,73"
"2,73",14400,"0,314","2,74"
"2,74",14400,"0,315","2,74"
"2,74",14400,"0,316","2,75"
"2,75",14500,"0,317","2,75"
"2,75",14500,"0,317","2,75"
"2,76",14500,"0,318","2,76"
"2,76",14500,"0,319","2,76"
"2,76",14600,"0,320","2,77"
"2,77",14600,"0,321","2,77"
"2,77",14600,"0,322","2,78"
"2,78",14700,"0,322","2,78"
"2,78",14700,"0,323","2,79"
"2,79",14700,"0,324","2,79"
"2,79",14700,"0,325","2,79"
"2,79",14800,"0,326","2,80"
"2,80",14800,"0,327","2,80"
"2,80",14800,"0,328","2,81"
"2,81",14900,"0,329","2,81"
"2,81",14900,"0,330","2,82"
"2,82",14900,"0,331","2,82"
"2,82",14900,"0,332","2,82"
"2,83",15000,"0,332","2,83"
"2,83",15000,"0,333","2,83"
"2,83",15000,"0,335","2,84"
"2,84",15000,"0,335","2,84"
"2,84",15100,"0,336","2,85"
"2,85",15100,"0,337","2,85"
"2,85",15100,"0,338","2,85"
"2,86",15200,"0,339","2,86"
"2,86",15200,"0,341","2,86"
"2,86",15200,"0,342","2,87"
"2,87",15200,"0,343","2,87"
"2,87",15300,"0,344","2,88"
"2,88",15300,"0,345","2,88"
"2,88",15300,"0,346","2,89"
"2,89",15300,"0,347","2,89"
"2,89",15400,"0,349","2,89"
"2,90",15400,"0,350","2,90"
"2,90",15400,"0,351","2,90"
"2,90",15500,"0,352","2,91"
"2,91",15500,"0,354","2,91"
"2,91",15500,"0,355","2,92"
"2,92",15500,"0,356","2,92"
"2,92",15600,"0,358","2,92"
"2,93",15600,"0,359","2,93"
"2,93",15600,"0,361","2,93"
"2,93",15600,"0,362","2,94"
"2,94",15700,"0,363","2,94"
"2,94",15700,"0,365","2,95"
"2,95",15700,"0,366","2,95"
"2,95",15700,"0,368","2,96"
"2,96",15800,"0,370","2,96"
"2,96",15800,"0,371","2,96"
"2,97",15800,"0,373","2,97"
"2,97",15800,"0,374","2,97"
"2,97",15900,"0,376","2,98"
"2,98",15900,"0,378","2,98"
"2,98",15900,"0,380","2,99"
"2,99",15900,"0,381","2,99"
"2,99",16000,"0,383","2,99"
"3,00",16000,"0,385","3,00"
"3,00",16000,"0,387","3,00"
"3,00",16000,"0,389","3,01"
"3,01",16100,"0,391","3,01"
"3,01",16100,"0,393","3,02"
"3,02",16100,"0,395","3,02"
"3,02",16100,"0,397","3,02"
"3,03",16200,"0,399","3,03"
"3,03",16200,"0,401","3,03"
"3,04",16200,"0,403","3,04"
"3,04",16200,"0,405","3,04"
"3,04",16300,"0,408","3,05"
"3,05",16300,"0,410","3,05"
"3,05",16300,"0,412","3,06"
"3,06",16300,"0,415","3,06"
"3,06",16300,"0,417","3,06"
"3,07",16400,"0,419","3,07"
"3,07",16400,"0,422","3,07"
"3,07",16400,"0,424","3,08"
"3,08",16400,"0,427","3,08"
"3,08",16400,"0,430","3,09"
"3,09",16500,"0,433","3,09"
"3,09",16500,"0,435","3,09"
"3,10",16500,"0,438","3,10"
"3,10",16500,"0,441","3,10"
"3,11",16500,"0,444","3,11"
"3,11",16600,"0,447","3,11"
"3,11",16600,"0,450","3,12"
"3,12",16600,"0,453","3,12"
"3,12",16600,"0,456","3,13"
"3,13",16600,"0,460","3,13"
"3,13",16600,"0,463","3,13"
"3,14",16700,"0,467","3,14"
"3,14",16700,"0,471","3,14"
"3,14",16700,"0,475","3,15"
"3,15",16700,"0,479","3,15"
"3,15",16700,"0,483","3,16"
"3,16",16700,"0,487","3,16"
"3,16",16700,"0,491","3,16"
"3,17",16700,"0,495","3,17"
"3,17",16800,"0,500","3,17"
"3,17",16800,"0,504","3,18"
"3,18",16800,"0,509","3,18"
"3,18",16800,"0,514","3,19"
"3,19",16800,"0,518","3,19"
"3,19",16800,"0,523","3,19"
"3,20",16800,"0,528","3,20"
"3,20",16800,"0,533","3,20"
"3,21",16800,"0,538","3,21"
"3,21",16800,"0,544","3,21"
"3,21",16800,"0,549","3,22"
"3,22",16900,"0,554","3,22"
"3,22",16900,"0,559","3,23"
"3,23",16900,"0,565","3,23"
"3,23",16900,"0,570","3,23"
"3,24",16900,"0,576","3,24"
"3,24",16900,"0,581","3,24"
"3,24",16900,"0,587","3,25"
"3,25",16900,"0,592","3,25"
"3,25",16900,"0,598","3,26"
"3,26",16900,"0,604","3,26"
"3,26",16900,"0,609","3,26"
"3,27",16900,"0,615","3,27"
"3,27",16900,"0,621","3,27"
"3,27",16900,"0,627","3,28"
"3,28",16900,"0,633","3,28"
"3,28",16900,"0,639","3,29"
"3,29",17000,"0,645","3,29"
"3,29",17000,"0,651","3,30"
"3,30",17000,"0,657","3,30"
"3,30",17000,"0,663","3,30"
"3,31",17000,"0,669","3,31"
"3,31",17000,"0,675","3,31"
"3,31",17000,"0,681","3,32"
"3,32",17000,"0,687","3,32"
"3,32",17000,"0,694","3,33"
"3,33",17000,"0,700","3,33"
"3,33",17000,"0,706","3,33"
"3,34",17000,"0,713","3,34"
"3,34",17000,"0,719","3,34"
"3,34",17000,"0,725","3,35"
"3,35",17000,"0,731","3,35"
"3,35",17000,"0,738","3,36"
"3,36",17000,"0,744","3,36"
"3,36",17000,"0,751","3,37"
"3,37",17000,"0,757","3,37"
"3,37",17000,"0,764","3,37"
"3,38",17000,"0,770","3,38"
"3,38",17000,"0,776","3,38"
"3,38",17000,"0,783","3,39"
"3,39",17000,"0,790","3,39"
"3,39",17100,"0,796","3,40"
"3,40",17100,"0,803","3,40"
"3,40",17100,"0,809","3,40"
"3,41",17100,"0,816","3,41"
"3,41",17100,"0,822","3,41"
"3,41",17100,"0,829","3,42"
"3,42",17100,"0,836","3,42"
"3,42",17100,"0,842","3,43"
"3,43",17100,"0,849","3,43"
"3,43",17100,"0,855","3,43"
"3,44",17100,"0,862","3,44"
"3,44",17100,"0,869","3,44"
"3,44",17100,"0,875","3,45"
"3,45",17100,"0,882","3,45"
"3,45",17100,"0,889","3,46"
"3,46",17100,"0,895","3,46"
"3,46",17100,"0,902","3,47"
"3,47",17100,"0,909","3,47"
"3,47",17100,"0,915","3,47"
"3,48",17100,"0,922","3,48"
"3,48",17100,"0,929","3,48"
"3,48",17100,"0,936","3,49"
"3,49",17100,"0,943","3,49"
"3,49",17100,"0,949","3,50"
"3,50",17100,"0,956","3,50"
"3,50",17100,"0,963","3,50"
"3,51",17100,"0,970","3,51"
"3,51",17100,"0,977","3,51"
"3,51",17100,"0,984","3,52"
"3,52",17100,"0,991","3,52"
"3,52",17100,"0,997","3,53"
"3,53",17100,"1,00","3,53"
"3,53",17200,"1,01","3,54"
"3,54",17200,"1,02","3,54"
"3,54",17200,"1,03","3,54"
"3,55",17200,"1,03","3,55"
"3,55",17200,"1,04","3,55"
"3,55",17200,"1,05","3,56"
"3,56",17200,"1,05","3,56"
"3,56",17200,"1,06","3,57"
"3,57",17200,"1,07","3,57"
"3,57",17200,"1,07","3,57"
"3,58",17200,"1,08","3,58"
"3,58",17200,"1,09","3,58"
"3,59",17200,"1,10","3,59"
"3,59",17200,"1,10","3,59"
"3,59",17200,"1,10","3,60"
"3,60",17200,"1,10","3,60"
"3,60",17200,"1,10","3,61"
"3,61",17200,"1,10","3,61"
"3,61",17200,"1,10","3,61"
"3,61",17200,"1,10","3,62"
"3,62",17200,"1,10","3,62"
"3,62",17200,"1,10","3,63"
"3,63",17200,"1,10","3,63"
"3,63",17200,"1,10","3,64"
"3,64",17200,"1,10","3,64"
"3,64",17200,"1,10","3,64"
"3,65",17200,"1,10","3,65"
"3,65",17200,"1,10","3,65"
"3,65",17200,"1,10","3,66"
"3,66",17200,"1,10","3,66"
"3,66",17200,"1,10","3,67"
"3,67",17200,"1,10","3,67"
"3,67",17200,"1,10","3,68"
"3,68",17200,"1,10","3,68"
"3,68",17200,"1,10","3,68"
"3,69",17200,"1,10","3,69"
"3,69",17200,"1,10","3,69"
"3,69",17200,"1,10","3,70"
"3,70",17200,"1,10","3,70"
"3,70",17200,"1,10","3,71"
"3,71",17200,"1,10","3,71"
"3,71",17300,"1,10","3,72"
"3,72",17300,"1,10","3,72"
"3,72",17300,"1,10","3,72"
"3,73",17300,"1,10","3,73"
"3,73",17300,"1,10","3,73"
"3,73",17300,"1,10","3,74"
"3,74",17300,"1,10","3,74"
"3,74",17300,"1,10","3,75"
"3,75",17300,"1,10","3,75"
"3,75",17300,"1,10","3,75"
"3,76",17300,"1,10","3,76"
"3,76",17300,"1,10","3,76"
"3,76",17300,"1,10","3,77"
"3,77",17300,"1,10","3,77"
"3,77",17300,"1,10","3,78"
"3,78",17300,"1,10","3,78"
"3,78",17300,"1,10","3,79"
"3,79",17300,"1,10","3,79"
"3,79",17300,"1,10","3,79"
"3,80",17300,"1,10","3,80"
"3,80",17300,"1,10","3,80"
"3,80",17300,"1,10","3,81"
"3,81",17300,"1,10","3,81"
"3,81",17300,"1,10","3,82"
"3,82",17300,"1,10","3,82"
"3,82",17300,"1,10","3,83"
"3,83",17300,"1,10","3,83"
"3,83",17300,"1,10","3,83"
"3,84",17300,"1,10","3,84"
"3,84",17300,"1,10","3,84"
"3,84",17300,"1,10","3,85"
"3,85",17300,"1,10","3,85"
"3,85",17300,"1,10","3,86"
"3,86",17300,"1,10","3,86"
"3,86",17300,"1,10","3,86"
"3,87",17300,"1,10","3,87"
"3,87",17300,"1,10","3,87"
"3,88",17300,"1,10","3,88"
"3,88",17300,"1,10","3,88"
"3,88",17300,"1,10","3,89"
"3,89",17300,"1,10","3,89"
"3,89",17300,"1,10","3,90"
"3,90",17300,"1,10","3,90"
"3,90",17400,"1,10","3,90"
"3,91",17400,"1,10","3,91"
"3,91",17400,"1,10","3,91"
"3,91",17400,"1,10","3,92"
"3,92",17400,"1,10","3,92"
"3,92",17400,"1,10","3,93"
"3,93",17400,"1,10","3,93"
"3,93",17400,"1,10","3,94"
"3,94",17400,"1,10","3,94"
"3,94",17400,"1,10","3,94"
"3,95",17400,"1,10","3,95"
"3,95",17400,"1,10","3,95"
"3,95",17400,"1,10","3,96"
"3,96",17400,"1,10","3,96"
"3,96",17400,"1,10","3,97"
"3,97",17400,"1,10","3,97"
"3,97",17400,"1,10","3,97"
"3,98",17400,"1,10","3,98"
"3,98",17400,"1,10","3,98"
"3,98",17400,"1,10","3,99"
"3,99",17400,"1,10","3,99"
"3,99",17400,"1,10","4,00"
"4,00",17400,"1,10","4,00"
"4,00",17400,"1,10","4,01"
"4,01",17400,"1,10","4,01"
"4,01",17400,"1,10","4,01"
"4,02",17400,"1,10","4,02"
"4,02",17400,"1,10","4,02"
"4,02",17400,"1,10","4,03"
"4,03",17400,"1,10","4,03"
"4,03",17400,"1,10","4,04"
"4,04",17400,"1,10","4,04"
"4,04",17400,"1,10","4,05"
"4,05",17400,"1,10","4,05"
"4,05",17400,"1,10","4,05"
"4,06",17400,"1,10","4,06"
"4,06",17400,"1,10","4,06"
"4,07",17400,"1,10","4,07"
"4,07",17400,"1,10","4,07"
"4,13",17800,"1,10","4,08"
"4,22",17700,"1,10","4,08"
"4,30",17700,"1,10","4,08"
"4,39",17700,"1,10","4,09"
"4,47",17800,"1,10","4,09"
"4,56",17800,"1,10","4,10"
"4,65",17800,"1,10","4,10"
"4,73",17900,"1,10","4,11"
"4,82",17900,"1,10","4,11"
"4,91",17900,"1,10","4,11"
"4,99",18000,"1,10","4,12"
"5,08",18000,"1,10","4,12"
"5,17",18000,"1,10","4,13"
"5,25",18100,"1,10","4,13"
"5,34",18100,"1,10","4,14"
"5,42",18100,"1,10","4,14"
"5,51",18200,"1,10","4,14"
"5,60",18200,"1,10","4,15"
"5,68",18200,"1,10","4,15"
"5,77",18200,"1,10","4,16"
"5,86",18300,"1,10","4,16"
"5,94",18300,"1,10","4,17"
"6,03",18300,"1,10","4,17"
"6,12",18300,"1,10","4,18"
"6,20",18300,"1,10","4,18"
"6,29",18300,"1,10","4,18"
"6,38",18400,"1,10","4,19"
"6,46",18400,"1,10","4,19"
"6,55",18400,"1,10","4,20"
"6,63",18400,"1,10","4,20"
"6,72",18400,"1,10","4,21"
"6,81",18400,"1,10","4,21"
"6,89",18400,"1,10","4,21"
"6,98",18400,"1,10","4,22"
"7,07",18400,"1,10","4,22"
"7,15",18400,"1,10","4,23"
"7,24",18400,"1,10","4,23"
"7,33",18300,"1,10","4,24"
"7,41",18300,"1,10","4,24"
"7,50",18300,"1,10","4,24"
"7,58",18200,"1,10","4,25"
"7,67",18100,"1,10","4,25"
"7,76",18100,"1,10","4,26"
"7,84",18000,"1,10","4,26"
"7,93",17900,"1,10","4,27"
"8,02",17800,"1,10","4,27"
"8,10",17700,"1,10","4,27"
"8,19",17500,"1,10","4,28"
"8,28",17400,"1,10","4,28"
"8,36",17300,"1,10","4,29"
"8,45",17100,"1,10","4,29"
"8,53",17000,"1,10","4,30"
"8,62",16800,"1,10","4,30"
"8,71",16700,"1,10","4,30"
"8,79",16500,"1,10","4,31"
"8,88",16400,"1,10","4,31"
"8,97",16200,"1,10","4,32"
"9,05",16000,"1,10","4,32"
"9,14",15800,"1,10","4,33"
"9,23",15600,"1,10","4,33"
"9,31",15400,"1,10","4,33"
"9,40",15200,"1,10","4,34"
"9,49",15000,"1,10","4,34"
"9,57",14800,"1,10","4,35"
"9,66",14600,"1,10","4,35"
"9,74",14300,"1,10","4,36"
"9,93",1730,"1,10","4,37"